Workbook

Sheet Task6 Posts
A1: Post ID | B1: Platform | C1: Date | D1: Content Type | E1: Post Text | F1: Post Text Hashtag | G1: Likes | H1: Shares | I1: Comments | J1: Impressions | K1: Reach | L1: Clicks | M1: Hashtags Used.1 | N1: Hashtags Used.2 | O1: Campaign_Name | P1: Engagement rate | Q1: ENGAGEMENT
A2: SP061 | B2: YouTube | C2: 45292 | D2: Reel | E2: Explore the latest podcasts now. | G2: 3437 | H2: 129 | I2: 359 | J2: 44558 | K2: 30854 | L2: 171 | M2: #DiscoverWeekly | N2: #SoundtrackOfLife | O2: SummerBeats | P2: =(G2+H2+I2)/J2 -> 0.088087437 | Q2: =G2+H2+I2 -> 3925
A3: SP126 | B3: Twitter | C3: 45295 | D3: Story | E3: Whatâ€™s your vibe today? | F3: SpotifyHits | G3: 3208 | H3: 476 | I3: 277 | J3: 56072 | K3: 21061 | L3: 113 | M3: #MusicForEveryone | N3: #NowPlaying | O3: ChillVibes | P3: =(G3+H3+I3)/J3 -> 0.070641318 | Q3: =G3+H3+I3 -> 3961
A4: SP281 | B4: Instagram | C4: 45298 | D4: Text | E4: Top trending tracks updated daily! | G4: 4931 | H4: 469 | I4: 193 | J4: 56701 | K4: 69437 | L4: 291 | M4: #SoundtrackOfLife | N4: #NowPlaying | O4: ChillVibes | P4: =(G4+H4+I4)/J4 -> 0.098640236 | Q4: =G4+H4+I4 -> 5593
A5: SP057 | B5: Instagram | C5: 45299 | D5: Text | E5: Top trending tracks updated daily! | G5: 2683 | H5: 405 | I5: 223 | J5: 31233 | K5: 58106 | L5: 291 | M5: #DiscoverWeekly | O5: IndieWave | P5: =(G5+H5+I5)/J5 -> 0.10600967 | Q5: =G5+H5+I5 -> 3311
A6: SP130 | B6: YouTube | C6: 45301 | D6: Text | E6: Explore the latest podcasts now. | G6: 1261 | H6: 190 | I6: 233 | J6: 59888 | K6: 51449 | L6: 205 | M6: #DiscoverWeekly | N6: #SpotifyWrapped | O6: IndieWave | P6: =(G6+H6+I6)/J6 -> 0.028119156 | Q6: =G6+H6+I6 -> 1684
A7: SP071 | B7: Twitter | C7: 45302 | D7: Text | E7: Whatâ€™s your vibe today? | F7: SpotifyHits | G7: 4218 | H7: 247 | I7: 183 | J7: 28914 | K7: 18310 | L7: 135 | M7: #SoundtrackOfLife | O7: IndieWave | P7: =(G7+H7+I7)/J7 -> 0.16075258 | Q7: =G7+H7+I7 -> 4648
A8: SP202 | B8: Twitter | C8: 45302 | D8: Story | E8: Wrapped is here! Relive your top tracks ðŸŽ§ | G8: 2340 | H8: 141 | I8: 206 | J8: 24916 | K8: 30582 | L8: 157 | M8: #SoundtrackOfLife | N8: #NowPlaying | O8: ChillVibes | P8: =(G8+H8+I8)/J8 -> 0.10784235 | Q8: =G8+H8+I8 -> 2687
A9: SP299 | B9: Twitter | C9: 45303 | D9: Story | E9: Wrapped is here! Relive your top tracks ðŸŽ§ | G9: 2227 | H9: 494 | I9: 161 | J9: 51651 | K9: 68074 | L9: 240 | M9: #DiscoverWeekly | N9: #MusicForEveryone | O9: ChillVibes | P9: =(G9+H9+I9)/J9 -> 0.055797564 | Q9: =G9+H9+I9 -> 2882
A10: SP079 | B10: YouTube | C10: 45304 | D10: Reel | E10: New music just dropped. Hit play! | G10: 4781 | H10: 191 | I10: 122 | J10: 35535 | K10: 50777 | L10: 128 | M10: #DiscoverWeekly | N10: #SoundtrackOfLife | O10: SummerBeats | P10: =(G10+H10+I10)/J10 -> 0.14335163 | Q10: =G10+H10+I10 -> 5094
A11: SP237 | B11: YouTube | C11: 45305 | D11: Text | E11: Whatâ€™s your vibe today? | F11: SpotifyHits | G11: 4502 | H11: 238 | I11: 386 | J11: 39198 | K11: 25050 | L11: 297 | M11: #DiscoverWeekly | N11: #SpotifyWrapped | O11: IndieWave | P11: =(G11+H11+I11)/J11 -> 0.13077198 | Q11: =G11+H11+I11 -> 5126
A12: SP195 | B12: YouTube | C12: 45305 | D12: Text | E12: New music just dropped. Hit play! | G12: 3634 | H12: 280 | I12: 399 | J12: 40256 | K12: 52605 | L12: 213 | M12: #DiscoverWeekly | N12: #SpotifyWrapped | O12: IndieWave | P12: =(G12+H12+I12)/J12 -> 0.10713931 | Q12: =G12+H12+I12 -> 4313
A13: SP226 | B13: Twitter | C13: 45308 | D13: Story | E13: New music just dropped. Hit play! | G13: 2174 | H13: 499 | I13: 212 | J13: 54938 | K13: 27190 | L13: 265 | M13: #MusicForEveryone | N13: #NowPlaying | O13: ChillVibes | P13: =(G13+H13+I13)/J13 -> 0.052513743 | Q13: =G13+H13+I13 -> 2885
A14: SP147 | B14: Twitter | C14: 45312 | D14: Story | E14: Discover fresh beats on Spotify! | G14: 2383 | H14: 136 | I14: 302 | J14: 39187 | K14: 22133 | L14: 208 | M14: #MusicForEveryone | N14: #NowPlaying | O14: ChillVibes | P14: =(G14+H14+I14)/J14 -> 0.071988159 | Q14: =G14+H14+I14 -> 2821
A15: SP075 | B15: Twitter | C15: 45313 | D15: Story | E15: From pop to podcasts, itâ€™s all here. | G15: 1554 | H15: 455 | I15: 158 | J15: 41947 | K15: 48578 | L15: 101 | M15: #SoundtrackOfLife | N15: #NowPlaying | O15: ChillVibes | P15: =(G15+H15+I15)/J15 -> 0.051660429 | Q15: =G15+H15+I15 -> 2167
A16: SP097 | B16: Instagram | C16: 45317 | D16: Text | E16: Whatâ€™s your vibe today? | F16: SpotifyHits | G16: 3878 | H16: 431 | I16: 97 | J16: 41763 | K16: 29729 | L16: 191 | M16: #DiscoverWeekly | O16: IndieWave | P16: =(G16+H16+I16)/J16 -> 0.10550008 | Q16: =G16+H16+I16 -> 4406
A17: SP133 | B17: YouTube | C17: 45318 | D17: Text | E17: Your weekend playlist is waiting. | G17: 1976 | H17: 262 | I17: 218 | J17: 51696 | K17: 44846 | L17: 139 | M17: #DiscoverWeekly | N17: #SpotifyWrapped | O17: IndieWave | P17: =(G17+H17+I17)/J17 -> 0.047508511 | Q17: =G17+H17+I17 -> 2456
A18: SP127 | B18: Twitter | C18: 45319 | D18: Text | E18: Music that moves youâ€”only on Spotify. | G18: 1456 | H18: 265 | I18: 137 | J18: 53485 | K18: 59729 | L18: 145 | M18: #SoundtrackOfLife | O18: IndieWave | P18: =(G18+H18+I18)/J18 -> 0.034738712 | Q18: =G18+H18+I18 -> 1858
A19: SP225 | B19: YouTube | C19: 45323 | D19: Text | E19: Wrapped is here! Relive your top tracks ðŸŽ§ | G19: 1432 | H19: 437 | I19: 267 | J19: 40634 | K19: 54511 | L19: 197 | M19: #DiscoverWeekly | N19: #SpotifyWrapped | O19: IndieWave | P19: =(G19+H19+I19)/J19 -> 0.052566816 | Q19: =G19+H19+I19 -> 2136
A20: SP234 | B20: Twitter | C20: 45324 | D20: Text | E20: From pop to podcasts, itâ€™s all here. | G20: 3818 | H20: 115 | I20: 286 | J20: 25127 | K20: 22277 | L20: 263 | M20: #NowPlaying | O20: ChillVibes | P20: =(G20+H20+I20)/J20 -> 0.16790703 | Q20: =G20+H20+I20 -> 4219
A21: SP018 | B21: Instagram | C21: 45325 | D21: Story | E21: Music that moves youâ€”only on Spotify. | G21: 4281 | H21: 101 | I21: 163 | J21: 32278 | K21: 53382 | L21: 235 | M21: #NowPlaying | O21: Wrapped2024 | P21: =(G21+H21+I21)/J21 -> 0.14080798 | Q21: =G21+H21+I21 -> 4545
A22: SP300 | B22: Instagram | C22: 45329 | D22: Text | E22: Music that moves youâ€”only on Spotify. | G22: 1883 | H22: 432 | I22: 397 | J22: 28759 | K22: 18691 | L22: 270 | M22: #SoundtrackOfLife | N22: #NowPlaying | O22: ChillVibes | P22: =(G22+H22+I22)/J22 -> 0.094300914 | Q22: =G22+H22+I22 -> 2712
A23: SP160 | B23: YouTube | C23: 45330 | D23: Reel | E23: Top trending tracks updated daily! | G23: 1889 | H23: 298 | I23: 122 | J23: 46225 | K23: 74305 | L23: 293 | M23: #DiscoverWeekly | N23: #SoundtrackOfLife | O23: SummerBeats | P23: =(G23+H23+I23)/J23 -> 0.049951325 | Q23: =G23+H23+I23 -> 2309
A24: SP219 | B24: Twitter | C24: 45332 | D24: Text | E24: From pop to podcasts, itâ€™s all here. | G24: 1519 | H24: 456 | I24: 379 | J24: 51611 | K24: 45880 | L24: 176 | M24: #SoundtrackOfLife | O24: IndieWave | P24: =(G24+H24+I24)/J24 -> 0.045610432 | Q24: =G24+H24+I24 -> 2354
A25: SP046 | B25: Instagram | C25: 45334 | D25: Text | E25: Explore the latest podcasts now. | G25: 2923 | H25: 330 | I25: 250 | J25: 23993 | K25: 74590 | L25: 92 | M25: #DiscoverWeekly | O25: IndieWave | P25: =(G25+H25+I25)/J25 -> 0.14600092 | Q25: =G25+H25+I25 -> 3503
A26: SP273 | B26: Twitter | C26: 45334 | D26: Text | E26: Explore the latest podcasts now. | G26: 2691 | H26: 486 | I26: 206 | J26: 51133 | K26: 44583 | L26: 276 | M26: #NowPlaying | O26: ChillVibes | P26: =(G26+H26+I26)/J26 -> 0.066160796 | Q26: =G26+H26+I26 -> 3383
A27: SP103 | B27: Instagram | C27: 45336 | D27: Text | E27: Music that moves youâ€”only on Spotify. | G27: 1830 | H27: 112 | I27: 181 | J27: 31870 | K27: 55742 | L27: 263 | M27: #SoundtrackOfLife | N27: #NowPlaying | O27: ChillVibes | P27: =(G27+H27+I27)/J27 -> 0.066614371 | Q27: =G27+H27+I27 -> 2123
A28: SP117 | B28: Instagram | C28: 45340 | D28: Story | E28: From pop to podcasts, itâ€™s all here. | G28: 1516 | H28: 215 | I28: 332 | J28: 58981 | K28: 36118 | L28: 211 | M28: #NowPlaying | O28: Wrapped2024 | P28: =(G28+H28+I28)/J28 -> 0.034977366 | Q28: =G28+H28+I28 -> 2063
A29: SP275 | B29: Instagram | C29: 45341 | D29: Text | E29: Wrapped is here! Relive your top tracks ðŸŽ§ | G29: 4752 | H29: 449 | I29: 309 | J29: 58530 | K29: 26630 | L29: 234 | M29: #DiscoverWeekly | O29: IndieWave | P29: =(G29+H29+I29)/J29 -> 0.094139757 | Q29: =G29+H29+I29 -> 5510
A30: SP282 | B30: Twitter | C30: 45343 | D30: Story | E30: Get into the groove with our new drop! | G30: 2604 | H30: 439 | I30: 148 | J30: 58468 | K30: 39629 | L30: 163 | M30: #MusicForEveryone | N30: #NowPlaying | O30: ChillVibes | P30: =(G30+H30+I30)/J30 -> 0.054576863 | Q30: =G30+H30+I30 -> 3191
A31: SP128 | B31: Instagram | C31: 45344 | D31: Text | E31: New music just dropped. Hit play! | G31: 1902 | H31: 394 | I31: 279 | J31: 24615 | K31: 51330 | L31: 176 | M31: #SoundtrackOfLife | N31: #NowPlaying | O31: ChillVibes | P31: =(G31+H31+I31)/J31 -> 0.10461101 | Q31: =G31+H31+I31 -> 2575
A32: SP191 | B32: YouTube | C32: 45346 | D32: Reel | E32: Discover fresh beats on Spotify! | G32: 4221 | H32: 307 | I32: 58 | J32: 45080 | K32: 37214 | L32: 240 | M32: #DiscoverWeekly | N32: #SoundtrackOfLife | O32: SummerBeats | P32: =(G32+H32+I32)/J32 -> 0.10173026 | Q32: =G32+H32+I32 -> 4586
A33: SP229 | B33: YouTube | C33: 45346 | D33: Text | E33: Music that moves youâ€”only on Spotify. | G33: 4653 | H33: 226 | I33: 349 | J33: 56876 | K33: 28452 | L33: 257 | M33: #DiscoverWeekly | N33: #SpotifyWrapped | O33: IndieWave | P33: =(G33+H33+I33)/J33 -> 0.091919263 | Q33: =G33+H33+I33 -> 5228
A34: SP122 | B34: Twitter | C34: 45346 | D34: Story | E34: Music that moves youâ€”only on Spotify. | G34: 1022 | H34: 463 | I34: 360 | J34: 51468 | K34: 24279 | L34: 230 | M34: #DiscoverWeekly | N34: #MusicForEveryone | O34: ChillVibes | P34: =(G34+H34+I34)/J34 -> 0.035847517 | Q34: =G34+H34+I34 -> 1845
A35: SP093 | B35: Instagram | C35: 45351 | D35: Text | E35: From pop to podcasts, itâ€™s all here. | G35: 1100 | H35: 229 | I35: 312 | J35: 25641 | K35: 34601 | L35: 169 | M35: #DiscoverWeekly | O35: IndieWave | P35: =(G35+H35+I35)/J35 -> 0.063999064 | Q35: =G35+H35+I35 -> 1641
A36: SP028 | B36: YouTube | C36: 45356 | D36: Reel | E36: Explore the latest podcasts now. | G36: 3558 | H36: 314 | I36: 199 | J36: 49612 | K36: 53929 | L36: 206 | M36: #DiscoverWeekly | N36: #SoundtrackOfLife | O36: SummerBeats | P36: =(G36+H36+I36)/J36 -> 0.08205676 | Q36: =G36+H36+I36 -> 4071
A37: SP249 | B37: Instagram | C37: 45357 | D37: Text | E37: Whatâ€™s your vibe today? | F37: SpotifyHits | G37: 3529 | H37: 263 | I37: 107 | J37: 26570 | K37: 19367 | L37: 96 | M37: #DiscoverWeekly | O37: IndieWave | P37: =(G37+H37+I37)/J37 -> 0.14674445 | Q37: =G37+H37+I37 -> 3899
A38: SP011 | B38: Twitter | C38: 45357 | D38: Text | E38: Discover fresh beats on Spotify! | G38: 1971 | H38: 370 | I38: 306 | J38: 31316 | K38: 27897 | L38: 88 | M38: #SoundtrackOfLife | O38: IndieWave | P38: =(G38+H38+I38)/J38 -> 0.084525482 | Q38: =G38+H38+I38 -> 2647
A39: SP047 | B39: YouTube | C39: 45365 | D39: Reel | E39: From pop to podcasts, itâ€™s all here. | G39: 3361 | H39: 188 | I39: 358 | J39: 39838 | K39: 24536 | L39: 120 | M39: #DiscoverWeekly | N39: #SoundtrackOfLife | O39: SummerBeats | P39: =(G39+H39+I39)/J39 -> 0.098072192 | Q39: =G39+H39+I39 -> 3907
A40: SP098 | B40: Twitter | C40: 45366 | D40: Story | E40: Get into the groove with our new drop! | G40: 4969 | H40: 433 | I40: 237 | J40: 59552 | K40: 23885 | L40: 157 | M40: #DiscoverWeekly | N40: #MusicForEveryone | O40: ChillVibes | P40: =(G40+H40+I40)/J40 -> 0.094690355 | Q40: =G40+H40+I40 -> 5639
...

Sheet Task 6.1
A1: Identify week with highest net follower gain
A4: Unique weeks | B4: New Followers Per Week | C4: Unfollower Per Week | D4: Net Follower Gain | F4: Max net follower --> | G4: =MAX(D5:D71) -> 3576
A5: {=_xlfn.UNIQUE('task 6 Engagement Summary'!A2:A201)} -> 45446 | B5: =SUMIFS('task 6 Engagement Summary'!$C$2:$C$201,'task 6 Engagement Summary'!$A$2:$A$201,'Task 6.1'!$A5) -> 3869 | C5: =SUMIFS('task 6 Engagement Summary'!$D$2:$D$201,'task 6 Engagement Summary'!$A$2:$A$201,'Task 6.1'!$A5) -> 450 | D5: =B5-C5 -> 3419 | F5: Week with highest net follwer gain --> | G5: =INDEX(_xlfn.ANCHORARRAY(A5),MATCH(G4,D5:D71,0)) -> 45600
A6: 45453 | B6: =SUMIFS('task 6 Engagement Summary'!$C$2:$C$201,'task 6 Engagement Summary'!$A$2:$A$201,'Task 6.1'!$A6) -> 3024 | C6: =SUMIFS('task 6 Engagement Summary'!$D$2:$D$201,'task 6 Engagement Summary'!$A$2:$A$201,'Task 6.1'!$A6) -> 247 | D6: =B6-C6 -> 2777
A7: 45460 | B7: =SUMIFS('task 6 Engagement Summary'!$C$2:$C$201,'task 6 Engagement Summary'!$A$2:$A$201,'Task 6.1'!$A7) -> 3767 | C7: =SUMIFS('task 6 Engagement Summary'!$D$2:$D$201,'task 6 Engagement Summary'!$A$2:$A$201,'Task 6.1'!$A7) -> 592 | D7: =B7-C7 -> 3175
A8: 45467 | B8: =SUMIFS('task 6 Engagement Summary'!$C$2:$C$201,'task 6 Engagement Summary'!$A$2:$A$201,'Task 6.1'!$A8) -> 3024 | C8: =SUMIFS('task 6 Engagement Summary'!$D$2:$D$201,'task 6 Engagement Summary'!$A$2:$A$201,'Task 6.1'!$A8) -> 591 | D8: =B8-C8 -> 2433
A9: 45474 | B9: =SUMIFS('task 6 Engagement Summary'!$C$2:$C$201,'task 6 Engagement Summary'!$A$2:$A$201,'Task 6.1'!$A9) -> 2849 | C9: =SUMIFS('task 6 Engagement Summary'!$D$2:$D$201,'task 6 Engagement Summary'!$A$2:$A$201,'Task 6.1'!$A9) -> 423 | D9: =B9-C9 -> 2426 | G9: FORMULA USED
A10: 45481 | B10: =SUMIFS('task 6 Engagement Summary'!$C$2:$C$201,'task 6 Engagement Summary'!$A$2:$A$201,'Task 6.1'!$A10) -> 3521 | C10: =SUMIFS('task 6 Engagement Summary'!$D$2:$D$201,'task 6 Engagement Summary'!$A$2:$A$201,'Task 6.1'!$A10) -> 366 | D10: =B10-C10 -> 3155 | G10: UNIQUE WEEKS=UNIQUE('task 6 Engagement Summary'!A2:A201)
A11: 45488 | B11: =SUMIFS('task 6 Engagement Summary'!$C$2:$C$201,'task 6 Engagement Summary'!$A$2:$A$201,'Task 6.1'!$A11) -> 2905 | C11: =SUMIFS('task 6 Engagement Summary'!$D$2:$D$201,'task 6 Engagement Summary'!$A$2:$A$201,'Task 6.1'!$A11) -> 536 | D11: =B11-C11 -> 2369
A12: 45495 | B12: =SUMIFS('task 6 Engagement Summary'!$C$2:$C$201,'task 6 Engagement Summary'!$A$2:$A$201,'Task 6.1'!$A12) -> 2654 | C12: =SUMIFS('task 6 Engagement Summary'!$D$2:$D$201,'task 6 Engagement Summary'!$A$2:$A$201,'Task 6.1'!$A12) -> 373 | D12: =B12-C12 -> 2281 | G12: NEW FOLLOWER PER WEEK =SUMIFS('task 6 Engagement Summary'!$C$2:$C$201,'task 6 Engagement Summary'!$A$2:$A$201,'Task 6.1'!$A7)
A13: 45502 | B13: =SUMIFS('task 6 Engagement Summary'!$C$2:$C$201,'task 6 Engagement Summary'!$A$2:$A$201,'Task 6.1'!$A13) -> 2567 | C13: =SUMIFS('task 6 Engagement Summary'!$D$2:$D$201,'task 6 Engagement Summary'!$A$2:$A$201,'Task 6.1'!$A13) -> 435 | D13: =B13-C13 -> 2132
A14: 45509 | B14: =SUMIFS('task 6 Engagement Summary'!$C$2:$C$201,'task 6 Engagement Summary'!$A$2:$A$201,'Task 6.1'!$A14) -> 3138 | C14: =SUMIFS('task 6 Engagement Summary'!$D$2:$D$201,'task 6 Engagement Summary'!$A$2:$A$201,'Task 6.1'!$A14) -> 445 | D14: =B14-C14 -> 2693
A15: 45516 | B15: =SUMIFS('task 6 Engagement Summary'!$C$2:$C$201,'task 6 Engagement Summary'!$A$2:$A$201,'Task 6.1'!$A15) -> 3625 | C15: =SUMIFS('task 6 Engagement Summary'!$D$2:$D$201,'task 6 Engagement Summary'!$A$2:$A$201,'Task 6.1'!$A15) -> 553 | D15: =B15-C15 -> 3072 | G15: UNFOLLOW PER WEEK =SUMIFS('task 6 Engagement Summary'!$D$2:$D$201,'task 6 Engagement Summary'!$A$2:$A$201,'Task 6.1'!$A7)
A16: 45523 | B16: =SUMIFS('task 6 Engagement Summary'!$C$2:$C$201,'task 6 Engagement Summary'!$A$2:$A$201,'Task 6.1'!$A16) -> 2813 | C16: =SUMIFS('task 6 Engagement Summary'!$D$2:$D$201,'task 6 Engagement Summary'!$A$2:$A$201,'Task 6.1'!$A16) -> 513 | D16: =B16-C16 -> 2300
A17: 45530 | B17: =SUMIFS('task 6 Engagement Summary'!$C$2:$C$201,'task 6 Engagement Summary'!$A$2:$A$201,'Task 6.1'!$A17) -> 3147 | C17: =SUMIFS('task 6 Engagement Summary'!$D$2:$D$201,'task 6 Engagement Summary'!$A$2:$A$201,'Task 6.1'!$A17) -> 697 | D17: =B17-C17 -> 2450
A18: 45537 | B18: =SUMIFS('task 6 Engagement Summary'!$C$2:$C$201,'task 6 Engagement Summary'!$A$2:$A$201,'Task 6.1'!$A18) -> 2915 | C18: =SUMIFS('task 6 Engagement Summary'!$D$2:$D$201,'task 6 Engagement Summary'!$A$2:$A$201,'Task 6.1'!$A18) -> 413 | D18: =B18-C18 -> 2502
A19: 45544 | B19: =SUMIFS('task 6 Engagement Summary'!$C$2:$C$201,'task 6 Engagement Summary'!$A$2:$A$201,'Task 6.1'!$A19) -> 3196 | C19: =SUMIFS('task 6 Engagement Summary'!$D$2:$D$201,'task 6 Engagement Summary'!$A$2:$A$201,'Task 6.1'!$A19) -> 566 | D19: =B19-C19 -> 2630 | G19: NET FOLLOWER GAIN =B7-C7
A20: 45551 | B20: =SUMIFS('task 6 Engagement Summary'!$C$2:$C$201,'task 6 Engagement Summary'!$A$2:$A$201,'Task 6.1'!$A20) -> 2739 | C20: =SUMIFS('task 6 Engagement Summary'!$D$2:$D$201,'task 6 Engagement Summary'!$A$2:$A$201,'Task 6.1'!$A20) -> 577 | D20: =B20-C20 -> 2162
A21: 45558 | B21: =SUMIFS('task 6 Engagement Summary'!$C$2:$C$201,'task 6 Engagement Summary'!$A$2:$A$201,'Task 6.1'!$A21) -> 3496 | C21: =SUMIFS('task 6 Engagement Summary'!$D$2:$D$201,'task 6 Engagement Summary'!$A$2:$A$201,'Task 6.1'!$A21) -> 711 | D21: =B21-C21 -> 2785 | G21: MAX NET FOLLOWER =MAX(D7:D73)
A22: 45565 | B22: =SUMIFS('task 6 Engagement Summary'!$C$2:$C$201,'task 6 Engagement Summary'!$A$2:$A$201,'Task 6.1'!$A22) -> 3835 | C22: =SUMIFS('task 6 Engagement Summary'!$D$2:$D$201,'task 6 Engagement Summary'!$A$2:$A$201,'Task 6.1'!$A22) -> 684 | D22: =B22-C22 -> 3151
A23: 45572 | B23: =SUMIFS('task 6 Engagement Summary'!$C$2:$C$201,'task 6 Engagement Summary'!$A$2:$A$201,'Task 6.1'!$A23) -> 2770 | C23: =SUMIFS('task 6 Engagement Summary'!$D$2:$D$201,'task 6 Engagement Summary'!$A$2:$A$201,'Task 6.1'!$A23) -> 432 | D23: =B23-C23 -> 2338 | G23: Week with highest net follwer gain --> =INDEX(A7#,MATCH(G6,D7:D73,0))
A24: 45579 | B24: =SUMIFS('task 6 Engagement Summary'!$C$2:$C$201,'task 6 Engagement Summary'!$A$2:$A$201,'Task 6.1'!$A24) -> 3206 | C24: =SUMIFS('task 6 Engagement Summary'!$D$2:$D$201,'task 6 Engagement Summary'!$A$2:$A$201,'Task 6.1'!$A24) -> 536 | D24: =B24-C24 -> 2670
A25: 45586 | B25: =SUMIFS('task 6 Engagement Summary'!$C$2:$C$201,'task 6 Engagement Summary'!$A$2:$A$201,'Task 6.1'!$A25) -> 3313 | C25: =SUMIFS('task 6 Engagement Summary'!$D$2:$D$201,'task 6 Engagement Summary'!$A$2:$A$201,'Task 6.1'!$A25) -> 521 | D25: =B25-C25 -> 2792
A26: 45593 | B26: =SUMIFS('task 6 Engagement Summary'!$C$2:$C$201,'task 6 Engagement Summary'!$A$2:$A$201,'Task 6.1'!$A26) -> 2940 | C26: =SUMIFS('task 6 Engagement Summary'!$D$2:$D$201,'task 6 Engagement Summary'!$A$2:$A$201,'Task 6.1'!$A26) -> 759 | D26: =B26-C26 -> 2181
A27: 45600 | B27: =SUMIFS('task 6 Engagement Summary'!$C$2:$C$201,'task 6 Engagement Summary'!$A$2:$A$201,'Task 6.1'!$A27) -> 4108 | C27: =SUMIFS('task 6 Engagement Summary'!$D$2:$D$201,'task 6 Engagement Summary'!$A$2:$A$201,'Task 6.1'!$A27) -> 532 | D27: =B27-C27 -> 3576 | G27: Or for Net Follower Gain We can Use =SUMIFS('task 6 Engagement Summary'!$C$2:$C$201,'task 6 Engagement Summary'!$A$2:$A$201,'Task 6.1'!$A7) - SUMIFS('task 6 Engagement Summary'!$D$2:$D$201,'task 6 Engagement Summary'!$A$2:$A$201,'Task 6.1'!$A7)
A28: 45607 | B28: =SUMIFS('task 6 Engagement Summary'!$C$2:$C$201,'task 6 Engagement Summary'!$A$2:$A$201,'Task 6.1'!$A28) -> 3194 | C28: =SUMIFS('task 6 Engagement Summary'!$D$2:$D$201,'task 6 Engagement Summary'!$A$2:$A$201,'Task 6.1'!$A28) -> 400 | D28: =B28-C28 -> 2794
A29: 45614 | B29: =SUMIFS('task 6 Engagement Summary'!$C$2:$C$201,'task 6 Engagement Summary'!$A$2:$A$201,'Task 6.1'!$A29) -> 2530 | C29: =SUMIFS('task 6 Engagement Summary'!$D$2:$D$201,'task 6 Engagement Summary'!$A$2:$A$201,'Task 6.1'!$A29) -> 595 | D29: =B29-C29 -> 1935
A30: 45621 | B30: =SUMIFS('task 6 Engagement Summary'!$C$2:$C$201,'task 6 Engagement Summary'!$A$2:$A$201,'Task 6.1'!$A30) -> 2930 | C30: =SUMIFS('task 6 Engagement Summary'!$D$2:$D$201,'task 6 Engagement Summary'!$A$2:$A$201,'Task 6.1'!$A30) -> 643 | D30: =B30-C30 -> 2287
A31: 45628 | B31: =SUMIFS('task 6 Engagement Summary'!$C$2:$C$201,'task 6 Engagement Summary'!$A$2:$A$201,'Task 6.1'!$A31) -> 2912 | C31: =SUMIFS('task 6 Engagement Summary'!$D$2:$D$201,'task 6 Engagement Summary'!$A$2:$A$201,'Task 6.1'!$A31) -> 529 | D31: =B31-C31 -> 2383
A32: 45635 | B32: =SUMIFS('task 6 Engagement Summary'!$C$2:$C$201,'task 6 Engagement Summary'!$A$2:$A$201,'Task 6.1'!$A32) -> 2104 | C32: =SUMIFS('task 6 Engagement Summary'!$D$2:$D$201,'task 6 Engagement Summary'!$A$2:$A$201,'Task 6.1'!$A32) -> 706 | D32: =B32-C32 -> 1398
A33: 45642 | B33: =SUMIFS('task 6 Engagement Summary'!$C$2:$C$201,'task 6 Engagement Summary'!$A$2:$A$201,'Task 6.1'!$A33) -> 3164 | C33: =SUMIFS('task 6 Engagement Summary'!$D$2:$D$201,'task 6 Engagement Summary'!$A$2:$A$201,'Task 6.1'!$A33) -> 471 | D33: =B33-C33 -> 2693
A34: 45649 | B34: =SUMIFS('task 6 Engagement Summary'!$C$2:$C$201,'task 6 Engagement Summary'!$A$2:$A$201,'Task 6.1'!$A34) -> 2956 | C34: =SUMIFS('task 6 Engagement Summary'!$D$2:$D$201,'task 6 Engagement Summary'!$A$2:$A$201,'Task 6.1'!$A34) -> 406 | D34: =B34-C34 -> 2550
A35: 45656 | B35: =SUMIFS('task 6 Engagement Summary'!$C$2:$C$201,'task 6 Engagement Summary'!$A$2:$A$201,'Task 6.1'!$A35) -> 2755 | C35: =SUMIFS('task 6 Engagement Summary'!$D$2:$D$201,'task 6 Engagement Summary'!$A$2:$A$201,'Task 6.1'!$A35) -> 418 | D35: =B35-C35 -> 2337
A36: 45663 | B36: =SUMIFS('task 6 Engagement Summary'!$C$2:$C$201,'task 6 Engagement Summary'!$A$2:$A$201,'Task 6.1'!$A36) -> 2906 | C36: =SUMIFS('task 6 Engagement Summary'!$D$2:$D$201,'task 6 Engagement Summary'!$A$2:$A$201,'Task 6.1'!$A36) -> 455 | D36: =B36-C36 -> 2451
A37: 45670 | B37: =SUMIFS('task 6 Engagement Summary'!$C$2:$C$201,'task 6 Engagement Summary'!$A$2:$A$201,'Task 6.1'!$A37) -> 2631 | C37: =SUMIFS('task 6 Engagement Summary'!$D$2:$D$201,'task 6 Engagement Summary'!$A$2:$A$201,'Task 6.1'!$A37) -> 290 | D37: =B37-C37 -> 2341
A38: 45677 | B38: =SUMIFS('task 6 Engagement Summary'!$C$2:$C$201,'task 6 Engagement Summary'!$A$2:$A$201,'Task 6.1'!$A38) -> 2547 | C38: =SUMIFS('task 6 Engagement Summary'!$D$2:$D$201,'task 6 Engagement Summary'!$A$2:$A$201,'Task 6.1'!$A38) -> 715 | D38: =B38-C38 -> 1832
A39: 45684 | B39: =SUMIFS('task 6 Engagement Summary'!$C$2:$C$201,'task 6 Engagement Summary'!$A$2:$A$201,'Task 6.1'!$A39) -> 2534 | C39: =SUMIFS('task 6 Engagement Summary'!$D$2:$D$201,'task 6 Engagement Summary'!$A$2:$A$201,'Task 6.1'!$A39) -> 606 | D39: =B39-C39 -> 1928
... A71: 45908 | B71: =SUMIFS('task 6 Engagement Summary'!$C$2:$C$201,'task 6 Engagement Summary'!$A$2:$A$201,'Task 6.1'!$A71) -> 1877 | C71: =SUMIFS('task 6 Engagement Summary'!$D$2:$D$201,'task 6 Engagement Summary'!$A$2:$A$201,'Task 6.1'!$A71) -> 441 | D71: =B71-C71 -> 1436

Sheet Task 6.2
A1: Moving average chart to analyze follower trends
A5: Row Labels | B5: Sum of Net Follower
A6: 45446 | B6: 3419
A7: 45453 | B7: 2777
A8: 45460 | B8: 3175
A9: 45467 | B9: 2433 | O9: The number of new followers changes a lot from week to week, with some big jumps and drops. But the dotted moving average line shows that, overall, follower growth is slowing down over time
A10: 45474 | B10: 2426
A11: 45481 | B11: 3155
A12: 45488 | B12: 2369
A13: 45495 | B13: 2281
A14: 45502 | B14: 2132
A15: 45509 | B15: 2693
A16: 45516 | B16: 3072
A17: 45523 | B17: 2300
A18: 45530 | B18: 2450
A19: 45537 | B19: 2502
A20: 45544 | B20: 2630
A21: 45551 | B21: 2162
... A72: 45908 | B72: 1436
A73: Grand Total | B73: 161588

Sheet Task 6.3
A1: Correlation between Ad Spend vs. Follower Growth
E3: correlation
A4: Week_Start_Date | B4: Ad_Spend | C4: Net Followers gain | E4: =CORREL(B5:B204,C5:C204) -> -0.01691599 | F4: Correlation between Ad Spend and Follower Growth (Net Followers gain): -0.017 This is very close to 0, meaning there is almost no correlation between ad spend and follower growth
A5: 45446 | B5: =_xlfn.XLOOKUP($A5,$A$5:$A$204,'task 6 Engagement Summary'!$G$2:$G$201,,0) -> 23125 | C5: 1334
A6: 45446 | B6: 22788 | C6: 909
A7: 45446 | B7: 7810 | C7: 1176
A8: 45453 | B8: 11966 | C8: 928
A9: 45453 | B9: 26298 | C9: 1397 | E9: Formula used
A10: 45453 | B10: 22029 | C10: 452 | E10: correlation between ad spend vs follower growth =CORREL(B5:B204,C5:C204)
A11: 45460 | B11: 12391 | C11: 590
A12: 45460 | B12: 14477 | C12: 1283
A13: 45460 | B13: 25040 | C13: 1302
A14: 45467 | B14: 22619 | C14: 612
A15: 45467 | B15: 12399 | C15: 1121
A16: 45467 | B16: 22456 | C16: 700
A17: 45474 | B17: 19328 | C17: 714
A18: 45474 | B18: 21107 | C18: 595
A19: 45474 | B19: 12277 | C19: 1117
A20: 45481 | B20: 11684 | C20: 667
A21: 45481 | B21: 14412 | C21: 1371
A22: 45481 | B22: 15924 | C22: 1117
... A204: 45908 | B204: 11418 | C204: 616

Sheet Dashboard

Sheet task 6 Engagement Summary
A1: Week_Start_Date | B1: Platform | C1: New_Followers | D1: Unfollows | E1: Total_Followers | F1: Engagement_Rate | G1: Ad_Spend | H1: Engagement_Rate % | I1: Net Growth | J1: Net Followers gain
A2: 45446 | B2: Instagram | C2: 1402 | D2: 68 | E2: 124562 | F2: 9.92 | G2: 23125 | H2: =F2/100 -> 0.0992 | I2: =(C2-D2)/E2 -> 0.010709526 | J2: =C2-D2 -> 1334
A3: 45446 | B3: Twitter | C3: 995 | D3: 86 | E3: 227958 | F3: 8.05 | G3: 22788 | H3: =F3/100 -> 0.0805 | I3: =(C3-D3)/E3 -> 0.0039875767 | J3: =C3-D3 -> 909 | L3: =CORREL(G2:G201,J2:J201) -> -0.01691599
A4: 45446 | B4: YouTube | C4: 1472 | D4: 296 | E4: 370242 | F4: 7.72 | G4: 7810 | H4: =F4/100 -> 0.0772 | I4: =(C4-D4)/E4 -> 0.0031763009 | J4: =C4-D4 -> 1176
A5: 45453 | B5: Instagram | C5: 1018 | D5: 90 | E5: 92474 | F5: 9.4 | G5: 11966 | H5: =F5/100 -> 0.094 | I5: =(C5-D5)/E5 -> 0.010035253 | J5: =C5-D5 -> 928
A6: 45453 | B6: Twitter | C6: 1461 | D6: 64 | E6: 328902 | F6: 9.02 | G6: 26298 | H6: =F6/100 -> 0.0902 | I6: =(C6-D6)/E6 -> 0.0042474658 | J6: =C6-D6 -> 1397
A7: 45453 | B7: YouTube | C7: 545 | D7: 93 | E7: 391621 | F7: 9.96 | G7: 22029 | H7: =F7/100 -> 0.0996 | I7: =(C7-D7)/E7 -> 0.0011541771 | J7: =C7-D7 -> 452
A8: 45460 | B8: Instagram | C8: 881 | D8: 291 | E8: 95885 | F8: 5.29 | G8: 12391 | H8: =F8/100 -> 0.0529 | I8: =(C8-D8)/E8 -> 0.0061532044 | J8: =C8-D8 -> 590
A9: 45460 | B9: Twitter | C9: 1414 | D9: 131 | E9: 245947 | F9: 8.3 | G9: 14477 | H9: =F9/100 -> 0.083 | I9: =(C9-D9)/E9 -> 0.005216571 | J9: =C9-D9 -> 1283
A10: 45460 | B10: YouTube | C10: 1472 | D10: 170 | E10: 250428 | F10: 4.66 | G10: 25040 | H10: =F10/100 -> 0.0466 | I10: =(C10-D10)/E10 -> 0.0051990991 | J10: =C10-D10 -> 1302
A11: 45467 | B11: Instagram | C11: 809 | D11: 197 | E11: 87186 | F11: 9.48 | G11: 22619 | H11: =F11/100 -> 0.0948 | I11: =(C11-D11)/E11 -> 0.0070194756 | J11: =C11-D11 -> 612
A12: 45467 | B12: Twitter | C12: 1371 | D12: 250 | E12: 128620 | F12: 7.11 | G12: 12399 | H12: =F12/100 -> 0.0711 | I12: =(C12-D12)/E12 -> 0.0087155963 | J12: =C12-D12 -> 1121
A13: 45467 | B13: YouTube | C13: 844 | D13: 144 | E13: 126015 | F13: 9.65 | G13: 22456 | H13: =F13/100 -> 0.0965 | I13: =(C13-D13)/E13 -> 0.0055548943 | J13: =C13-D13 -> 700
A14: 45474 | B14: Instagram | C14: 786 | D14: 72 | E14: 178615 | F14: 5.43 | G14: 19328 | H14: =F14/100 -> 0.0543 | I14: =(C14-D14)/E14 -> 0.0039974246 | J14: =C14-D14 -> 714
A15: 45474 | B15: Twitter | C15: 845 | D15: 250 | E15: 218228 | F15: 4.52 | G15: 21107 | H15: =F15/100 -> 0.0452 | I15: =(C15-D15)/E15 -> 0.0027265062 | J15: =C15-D15 -> 595
... A201: 45908 | B201: Twitter | C201: 860 | D201: 244 | E201: 348686 | F201: 5.12 | G201: 11418 | H201: =F201/100 -> 0.0512 | I201: =(C201-D201)/E201 -> 0.0017666324 | J201: =C201-D201 -> 616
H205: Formula used==F2/100( to convert it into percentage)

Sheet Campaign Metadata
A1: Campaign_Name | B1: Start_Date | C1: End_Date | D1: Objective | E1: Total_Budget | F1: Target_Platforms | G1: Primary_Hashtags.1 | H1: Primary_Hashtags.1
A2: SummerBeats | B2: 45458 | C2: 45488 | D2: Brand Awareness | E2: 175000 | F2: Instagram,YouTube | G2: #SpotifyWrapped | H2: #MusicForEveryone
A3: Wrapped2024 | B3: 45627 | C3: 45657 | D3: Engagement | E3: 225000 | F3: Twitter,YouTube | G3: #SpotifyWrapped | H3: #NowPlaying
A4: ChillVibes | B4: 45667 | C4: 45698 | D4: Product Launch | E4: 200000 | F4: Instagram,Twitter | G4: #ChillVibes | H4: #SoundtrackOfLife
A5: IndieWave | B5: 45717 | C5: 45747 | D5: Traffic | E5: 160000 | F5: Facebook,Instagram | G5: #DiscoverWeekly | H5: #IndieWave

Sheet Post2
A1: Post ID | B1: Platform | C1: Date | D1: Content Type | E1: Post Text | F1: Post Text Hashtag | G1: Likes | H1: Shares | I1: Comments | J1: Impressions | K1: Reach | L1: Clicks | M1: Campaign_Name | N1: Engagement rate per platform | O1: HASHTAG USED
A2: SP007 | B2: Twitter | C2: 45645 | D2: Story | E2: Get into the groove with our new drop! | G2: 4674 | H2: 409 | I2: 327 | J2: 20756 | K2: 63599 | L2: 212 | M2: ChillVibes | N2: 0.26064752 | O2: #SoundtrackOfLife
A3: SP007 | B3: Twitter | C3: 45645 | D3: Story | E3: Get into the groove with our new drop! | G3: 4674 | H3: 409 | I3: 327 | J3: 20756 | K3: 63599 | L3: 212 | M3: ChillVibes | N3: 0.26064752 | O3: #NowPlaying
A4: SP106 | B4: Twitter | C4: 45677 | D4: Story | E4: New music just dropped. Hit play! | G4: 4619 | H4: 272 | I4: 57 | J4: 21334 | K4: 46292 | L4: 91 | M4: ChillVibes | N4: 0.23193025 | O4: #SoundtrackOfLife
A5: SP106 | B5: Twitter | C5: 45677 | D5: Story | E5: New music just dropped. Hit play! | G5: 4619 | H5: 272 | I5: 57 | J5: 21334 | K5: 46292 | L5: 91 | M5: ChillVibes | N5: 0.23193025 | O5: #NowPlaying
A6: SP186 | B6: Twitter | C6: 45459 | D6: Story | E6: Explore the latest podcasts now. | G6: 4618 | H6: 312 | I6: 254 | J6: 22571 | K6: 29453 | L6: 197 | M6: ChillVibes | N6: 0.22967525 | O6: #MusicForEveryone
A7: SP186 | B7: Twitter | C7: 45459 | D7: Story | E7: Explore the latest podcasts now. | G7: 4618 | H7: 312 | I7: 254 | J7: 22571 | K7: 29453 | L7: 197 | M7: ChillVibes | N7: 0.22967525 | O7: #NowPlaying
A8: SP279 | B8: Twitter | C8: 45676 | D8: Story | E8: New music just dropped. Hit play! | G8: 3507 | H8: 295 | I8: 371 | J8: 20410 | K8: 53965 | L8: 212 | M8: ChillVibes | N8: 0.2044586 | O8: #SoundtrackOfLife
A9: SP279 | B9: Twitter | C9: 45676 | D9: Story | E9: New music just dropped. Hit play! | G9: 3507 | H9: 295 | I9: 371 | J9: 20410 | K9: 53965 | L9: 212 | M9: ChillVibes | N9: 0.2044586 | O9: #NowPlaying
A10: SP050 | B10: Twitter | C10: 45769 | D10: Text | E10: Discover fresh beats on Spotify! | G10: 4401 | H10: 421 | I10: 216 | J10: 24890 | K10: 54361 | L10: 148 | M10: ChillVibes | N10: 0.20241061 | O10: #NowPlaying
A11: SP022 | B11: Instagram | C11: 45823 | D11: Text | E11: Whatâ€™s your vibe today? | F11: SpotifyHits | G11: 4896 | H11: 466 | I11: 233 | J11: 28621 | K11: 34270 | L11: 84 | M11: ChillVibes | N11: 0.19548583 | O11: #SoundtrackOfLife
A12: SP022 | B12: Instagram | C12: 45823 | D12: Text | E12: Whatâ€™s your vibe today? | F12: SpotifyHits | G12: 4896 | H12: 466 | I12: 233 | J12: 28621 | K12: 34270 | L12: 84 | M12: ChillVibes | N12: 0.19548583 | O12: #NowPlaying
A13: SP157 | B13: YouTube | C13: 45718 | D13: Text | E13: From pop to podcasts, itâ€™s all here. | G13: 4425 | H13: 185 | I13: 162 | J13: 24610 | K13: 21342 | L13: 158 | M13: IndieWave | N13: 0.19390492 | O13: #DiscoverWeekly
A14: SP157 | B14: YouTube | C14: 45718 | D14: Text | E14: From pop to podcasts, itâ€™s all here. | G14: 4425 | H14: 185 | I14: 162 | J14: 24610 | K14: 21342 | L14: 158 | M14: IndieWave | N14: 0.19390492 | O14: #SpotifyWrapped
A15: SP248 | B15: YouTube | C15: 45457 | D15: Reel | E15: Wrapped is here! Relive your top tracks ðŸŽ§ | G15: 4722 | H15: 310 | I15: 344 | J15: 27911 | K15: 19000 | L15: 225 | M15: SummerBeats | N15: 0.19261223 | O15: #DiscoverWeekly
A16: SP248 | B16: YouTube | C16: 45457 | D16: Reel | E16: Wrapped is here! Relive your top tracks ðŸŽ§ | G16: 4722 | H16: 310 | I16: 344 | J16: 27911 | K16: 19000 | L16: 225 | M16: SummerBeats | N16: 0.19261223 | O16: #SoundtrackOfLife
A17: SP136 | B17: Twitter | C17: 45615 | D17: Text | E17: Top trending tracks updated daily! | G17: 3728 | H17: 271 | I17: 275 | J17: 22827 | K17: 37034 | L17: 199 | M17: ChillVibes | N17: 0.18723442 | O17: #NowPlaying
A18: SP068 | B18: Twitter | C18: 45379 | D18: Text | E18: Music that moves youâ€”only on Spotify. | G18: 3276 | H18: 421 | I18: 114 | J18: 20580 | K18: 30324 | L18: 221 | M18: IndieWave | N18: 0.18517979 | O18: #SoundtrackOfLife
A19: SP088 | B19: Twitter | C19: 45705 | D19: Story | E19: Whatâ€™s your vibe today? | F19: SpotifyHits | G19: 4796 | H19: 427 | I19: 339 | J19: 30752 | K19: 33870 | L19: 298 | M19: ChillVibes | N19: 0.18086629 | O19: #SoundtrackOfLife
A20: SP088 | B20: Twitter | C20: 45705 | D20: Story | E20: Whatâ€™s your vibe today? | F20: SpotifyHits | G20: 4796 | H20: 427 | I20: 339 | J20: 30752 | K20: 33870 | L20: 298 | M20: ChillVibes | N20: 0.18086629 | O20: #NowPlaying
A21: SP213 | B21: Instagram | C21: 45832 | D21: Story | E21: Get into the groove with our new drop! | G21: 4902 | H21: 422 | I21: 376 | J21: 31674 | K21: 53225 | L21: 147 | M21: Wrapped2024 | N21: 0.17995833 | O21: #NowPlaying
A22: SP250 | B22: Twitter | C22: 45792 | D22: Text | E22: Your weekend playlist is waiting. | G22: 4782 | H22: 210 | I22: 311 | J22: 29793 | K22: 37543 | L22: 145 | M22: ChillVibes | N22: 0.17799483 | O22: #NowPlaying
A23: SP067 | B23: YouTube | C23: 45384 | D23: Reel | E23: Your weekend playlist is waiting. | G23: 4563 | H23: 488 | I23: 356 | J23: 30619 | K23: 23328 | L23: 267 | M23: SummerBeats | N23: 0.1765897 | O23: #DiscoverWeekly
A24: SP067 | B24: YouTube | C24: 45384 | D24: Reel | E24: Your weekend playlist is waiting. | G24: 4563 | H24: 488 | I24: 356 | J24: 30619 | K24: 23328 | L24: 267 | M24: SummerBeats | N24: 0.1765897 | O24: #SoundtrackOfLife
A25: SP090 | B25: Twitter | C25: 45495 | D25: Story | E25: Wrapped is here! Relive your top tracks ðŸŽ§ | G25: 3336 | H25: 229 | I25: 337 | J25: 22117 | K25: 26205 | L25: 160 | M25: ChillVibes | N25: 0.17642537 | O25: #MusicForEveryone
A26: SP090 | B26: Twitter | C26: 45495 | D26: Story | E26: Wrapped is here! Relive your top tracks ðŸŽ§ | G26: 3336 | H26: 229 | I26: 337 | J26: 22117 | K26: 26205 | L26: 160 | M26: ChillVibes | N26: 0.17642537 | O26: #NowPlaying
A27: SP177 | B27: Twitter | C27: 45606 | D27: Text | E27: Explore the latest podcasts now. | G27: 4823 | H27: 489 | I27: 302 | J27: 32470 | K27: 31861 | L27: 178 | M27: IndieWave | N27: 0.17289806 | O27: #SoundtrackOfLife
A28: SP239 | B28: Twitter | C28: 45639 | D28: Story | E28: New music just dropped. Hit play! | G28: 4984 | H28: 300 | I28: 338 | J28: 32900 | K28: 31691 | L28: 160 | M28: ChillVibes | N28: 0.17088146 | O28: #MusicForEveryone
A29: SP239 | B29: Twitter | C29: 45639 | D29: Story | E29: New music just dropped. Hit play! | G29: 4984 | H29: 300 | I29: 338 | J29: 32900 | K29: 31691 | L29: 160 | M29: ChillVibes | N29: 0.17088146 | O29: #NowPlaying
A30: SP234 | B30: Twitter | C30: 45324 | D30: Text | E30: From pop to podcasts, itâ€™s all here. | G30: 3818 | H30: 115 | I30: 286 | J30: 25127 | K30: 22277 | L30: 263 | M30: ChillVibes | N30: 0.16790703 | O30: #NowPlaying
A31: SP183 | B31: Twitter | C31: 45496 | D31: Text | E31: Top trending tracks updated daily! | G31: 3204 | H31: 398 | I31: 85 | J31: 22020 | K31: 58353 | L31: 286 | M31: IndieWave | N31: 0.16743869 | O31: #SoundtrackOfLife
A32: SP111 | B32: YouTube | C32: 45493 | D32: Reel | E32: Music that moves youâ€”only on Spotify. | G32: 4955 | H32: 299 | I32: 345 | J32: 33644 | K32: 43547 | L32: 194 | M32: SummerBeats | N32: 0.16641898 | O32: #DiscoverWeekly
... A46: SP158 | B46: Twitter | C46: 45737 | D46: Story | E46: New music just dropped. Hit play! | G46: 4609 | H46: 427 | I46: 395 | J46: 33698 | K46: 29259 | L46: 216 | M46: ChillVibes | N46: 0.16116683 | O46: #MusicForEveryone
A47: SP071 | B47: Twitter | C47: 45302 | D47: Text | E47: Whatâ€™s your vibe today? | F47: SpotifyHits | G47: 4218 | H47: 247 | I47: 183 | J47: 28914 | K47: 18310 | L47: 135 | M47: IndieWave | N47: 0.16075258 | O47: #SoundtrackOfLife
A48: SP110 | B48: Instagram | C48: 45469 | D48: Text | E48: New music just dropped. Hit play! | G48: 3253 | H48: 483 | I48: 336 | J48: 25397 | K48: 51485 | L48: 131 | M48: IndieWave | N48: 0.1603339 | O48: #DiscoverWeekly
A49: SP048 | B49: Instagram | C49: 45693 | D49: Story | E49: Music that moves youâ€”only on Spotify. | G49: 3074 | H49: 371 | I49: 348 | J49: 24104 | K49: 57803 | L49: 213 | M49: Wrapped2024 | N49: 0.15735977 | O49: #NowPlaying
A50: SP290 | B50: Twitter | C50: 45517 | D50: Text | E50: Explore the latest podcasts now. | G50: 3418 | H50: 107 | I50: 221 | J50: 23927 | K50: 26182 | L50: 155 | M50: IndieWave | N50: 0.15655954 | O50: #SoundtrackOfLife
A51: SP161 | B51: Instagram | C51: 45803 | D51: Text | E51: Discover fresh beats on Spotify! | G51: 3086 | H51: 148 | I51: 310 | J51: 22824 | K51: 58103 | L51: 275 | M51: IndieWave | N51: 0.15527515 | O51: #DiscoverWeekly
A52: SP170 | B52: Twitter | C52: 45619 | D52: Text | E52: New music just dropped. Hit play! | G52: 4318 | H52: 371 | I52: 329 | J52: 32347 | K52: 68956 | L52: 259 | M52: IndieWave | N52: 0.15513031 | O52: #SoundtrackOfLife
A53: SP254 | B53: Twitter | C53: 45691 | D53: Text | E53: Whatâ€™s your vibe today? | F53: SpotifyHits | G53: 4995 | H53: 231 | I53: 94 | J53: 34431 | K53: 32560 | L53: 262 | M53: ChillVibes | N53: 0.15451192 | O53: #NowPlaying
...
